Workbook

Sheet 🏠 الصفحة الرئيسية
A1: نظام إدارة الوثائق والسجلات المؤسسية
A2: معهد التعليم المتقدم - نظام الأرشفة الإلكترونية الذكي
B4: 📊 لوحة المعلومات والإحصائيات العامة | I4: =D17
B6: القسم | C6: عدد المستندات | D6: مستندات سرية | E6: آخر تحديث | F6: الحالة
B7: شؤون الطلاب | C7: =COUNTIF('شؤون الطلاب'!G7:G100,"سري")+COUNTIF('شؤون الطلاب'!G7:G100,"سري للغاية")+COUNTIF('شؤون الطلاب'!G7:G100,"مهم") | D7: =COUNTA('شؤون الطلاب'!B7:B100) | E7: 2026-01-02 | F7: نشط
B8: التحصيل المالي | C8: =COUNTIF('التحصيل المالي'!G7:G100,"سري")+COUNTIF('التحصيل المالي'!G7:G100,"سري للغاية")+COUNTIF('التحصيل المالي'!G7:G100,"مهم") | D8: =COUNTA('التحصيل المالي'!B7:B100) | E8: 2026-01-01 | F8: نشط
B9: الشؤون المالية | C9: =COUNTIF('الشؤون المالية'!G7:G100,"سري")+COUNTIF('الشؤون المالية'!G7:G100,"سري للغاية")+COUNTIF('الشؤون المالية'!G7:G100,"مهم") | D9: =COUNTA('الشؤون المالية'!B7:B100) | E9: 2026-01-02 | F9: نشط
B10: الإدارة الأكاديمية | C10: =COUNTIF('الإدارة الأكاديمية'!G7:G100,"سري")+COUNTIF('الإدارة الأكاديمية'!G7:G100,"سري للغاية")+COUNTIF('الإدارة الأكاديمية'!G7:G100,"مهم") | D10: =COUNTA('الإدارة الأكاديمية'!B7:B100) | E10: 2025-12-31 | F10: نشط
B11: إدارة الجودة | C11: =COUNTIF('إدارة الجودة'!G7:G100,"سري")+COUNTIF('إدارة الجودة'!G7:G100,"سري للغاية")+COUNTIF('إدارة الجودة'!G7:G100,"مهم") | D11: =COUNTA('إدارة الجودة'!B7:B100) | E11: 2026-01-02 | F11: نشط
B12: الإدارة العليا | C12: =COUNTIF('الإدارة العليا'!G7:G100,"سري")+COUNTIF('الإدارة العليا'!G7:G100,"سري للغاية")+COUNTIF('الإدارة العليا'!G7:G100,"مهم") | D12: =COUNTA('الإدارة العليا'!B7:B100) | E12: 2025-12-30 | F12: نشط
B13: المرافق والصيانة | C13: =COUNTIF('المرافق والصيانة'!G7:G100,"سري")+COUNTIF('المرافق والصيانة'!G7:G100,"سري للغاية")+COUNTIF('المرافق والصيانة'!G7:G100,"مهم") | D13: =COUNTA('المرافق والصيانة'!B7:B100) | E13: 2026-01-01 | F13: نشط
B15: 📈 الإحصائيات الإجمالية
B17: إجمالي المستندات | D17: =SUM(D7:D13)
B18: إجمالي المستندات السرية | D18: =SUM(C7:C13)
B19: عدد الأقسام النشطة | D19: =COUNTA(B7:B13)
B21: 🔗 روابط سريعة للأقسام
B23: 📚 شؤون الطلاب
B24: 💰 التحصيل المالي
B25: 🏦 الشؤون المالية
B26: 🎓 الإدارة الأكاديمية
B27: ⭐ إدارة الجودة
B28: 👔 الإدارة العليا
B29: 🔧 المرافق والصيانة
B31: 📋 السجل الرئيسي للمستندات
B32: 🔒 المستندات السرية
B33: 📊 التقارير والإحصائيات
B34: 📖 دليل الاستخدام
B36: تم التحديث: 2026-01-02 | النظام مُصمم بواسطة إدارة تقنية المعلومات

Sheet السجل الرئيسي
A1: 📋 السجل الرئيسي للمستندات
A2: قاعدة البيانات الشاملة لجميع مستندات المعهد
A4: 🔙 العودة للصفحة الرئيسية | F4: إجمالي المستندات المسجلة: | I4: =COUNTA(B7:B1000)-1
B6: رقم المستند | C6: نوع المستند | D6: القسم المختص | E6: التاريخ | F6: موضوع المستند | G6: الحالة | H6: مستوى السرية | I6: الرابط الإلكتروني | J6: صادر/وارد | K6: ملاحظات | L6: مصدر المستند | M6: 🔐 كلمة السر
M7: =IF(OR(H7="سري",H7="سري للغاية",H7="مهم"),CONCATENATE("SEC-",TEXT(ROW(),"000"),"-",TEXT(RANDBETWEEN(1000,9999),"0000")),"")
M8: =IF(OR(H8="سري",H8="سري للغاية",H8="مهم"),CONCATENATE("SEC-",TEXT(ROW(),"000"),"-",TEXT(RANDBETWEEN(1000,9999),"0000")),"")
M9: =IF(OR(H9="سري",H9="سري للغاية",H9="مهم"),CONCATENATE("SEC-",TEXT(ROW(),"000"),"-",TEXT(RANDBETWEEN(1000,9999),"0000")),"")
M10: =IF(OR(H10="سري",H10="سري للغاية",H10="مهم"),CONCATENATE("SEC-",TEXT(ROW(),"000"),"-",TEXT(RANDBETWEEN(1000,9999),"0000")),"")
M11: =IF(OR(H11="سري",H11="سري للغاية",H11="مهم"),CONCATENATE("SEC-",TEXT(ROW(),"000"),"-",TEXT(RANDBETWEEN(1000,9999),"0000")),"")
M12: =IF(OR(H12="سري",H12="سري للغاية",H12="مهم"),CONCATENATE("SEC-",TEXT(ROW(),"000"),"-",TEXT(RANDBETWEEN(1000,9999),"0000")),"")
M13: =IF(OR(H13="سري",H13="سري للغاية",H13="مهم"),CONCATENATE("SEC-",TEXT(ROW(),"000"),"-",TEXT(RANDBETWEEN(1000,9999),"0000")),"")
M14: =IF(OR(H14="سري",H14="سري للغاية",H14="مهم"),CONCATENATE("SEC-",TEXT(ROW(),"000"),"-",TEXT(RANDBETWEEN(1000,9999),"0000")),"")
M15: =IF(OR(H15="سري",H15="سري للغاية",H15="مهم"),CONCATENATE("SEC-",TEXT(ROW(),"000"),"-",TEXT(RANDBETWEEN(1000,9999),"0000")),"")
M16: =IF(OR(H16="سري",H16="سري للغاية",H16="مهم"),CONCATENATE("SEC-",TEXT(ROW(),"000"),"-",TEXT(RANDBETWEEN(1000,9999),"0000")),"")
M17: =IF(OR(H17="سري",H17="سري للغاية",H17="مهم"),CONCATENATE("SEC-",TEXT(ROW(),"000"),"-",TEXT(RANDBETWEEN(1000,9999),"0000")),"")
M18: =IF(OR(H18="سري",H18="سري للغاية",H18="مهم"),CONCATENATE("SEC-",TEXT(ROW(),"000"),"-",TEXT(RANDBETWEEN(1000,9999),"0000")),"")
... M38: =IF(OR(H38="سري",H38="سري للغاية",H38="مهم"),CONCATENATE("SEC-",TEXT(ROW(),"000"),"-",TEXT(RANDBETWEEN(1000,9999),"0000")),"")
A39: ✅ المزامنة التلقائية نشطة! المستندات من صفحات الأقسام تظهر هنا فوراً. 🔐 المستندات السرية محمية بكلمة سر تلقائية في العمود M | M39: =IF(OR(H39="سري",H39="سري للغاية",H39="مهم"),CONCATENATE("SEC-",TEXT(ROW(),"000"),"-",TEXT(RANDBETWEEN(1000,9999),"0000")),"")
M40: =IF(OR(H40="سري",H40="سري للغاية",H40="مهم"),CONCATENATE("SEC-",TEXT(ROW(),"000"),"-",TEXT(RANDBETWEEN(1000,9999),"0000")),"")
M41: =IF(OR(H41="سري",H41="سري للغاية",H41="مهم"),CONCATENATE("SEC-",TEXT(ROW(),"000"),"-",TEXT(RANDBETWEEN(1000,9999),"0000")),"")
M42: =IF(OR(H42="سري",H42="سري للغاية",H42="مهم"),CONCATENATE("SEC-",TEXT(ROW(),"000"),"-",TEXT(RANDBETWEEN(1000,9999),"0000")),"")
M43: =IF(OR(H43="سري",H43="سري للغاية",H43="مهم"),CONCATENATE("SEC-",TEXT(ROW(),"000"),"-",TEXT(RANDBETWEEN(1000,9999),"0000")),"")
M44: =IF(OR(H44="سري",H44="سري للغاية",H44="مهم"),CONCATENATE("SEC-",TEXT(ROW(),"000"),"-",TEXT(RANDBETWEEN(1000,9999),"0000")),"")
M45: =IF(OR(H45="سري",H45="سري للغاية",H45="مهم"),CONCATENATE("SEC-",TEXT(ROW(),"000"),"-",TEXT(RANDBETWEEN(1000,9999),"0000")),"")
M46: =IF(OR(H46="سري",H46="سري للغاية",H46="مهم"),CONCATENATE("SEC-",TEXT(ROW(),"000"),"-",TEXT(RANDBETWEEN(1000,9999),"0000")),"")
M47: =IF(OR(H47="سري",H47="سري للغاية",H47="مهم"),CONCATENATE("SEC-",TEXT(ROW(),"000"),"-",TEXT(RANDBETWEEN(1000,9999),"0000")),"")
M48: =IF(OR(H48="سري",H48="سري للغاية",H48="مهم"),CONCATENATE("SEC-",TEXT(ROW(),"000"),"-",TEXT(RANDBETWEEN(1000,9999),"0000")),"")
M49: =IF(OR(H49="سري",H49="سري للغاية",H49="مهم"),CONCATENATE("SEC-",TEXT(ROW(),"000"),"-",TEXT(RANDBETWEEN(1000,9999),"0000")),"")
M50: =IF(OR(H50="سري",H50="سري للغاية",H50="مهم"),CONCATENATE("SEC-",TEXT(ROW(),"000"),"-",TEXT(RANDBETWEEN(1000,9999),"0000")),"")
M51: =IF(OR(H51="سري",H51="سري للغاية",H51="مهم"),CONCATENATE("SEC-",TEXT(ROW(),"000"),"-",TEXT(RANDBETWEEN(1000,9999),"0000")),"")
... M100: =IF(OR(H100="سري",H100="سري للغاية",H100="مهم"),CONCATENATE("SEC-",TEXT(ROW(),"000"),"-",TEXT(RANDBETWEEN(1000,9999),"0000")),"")

Sheet شؤون الطلاب
A1: 📚 قسم شؤون الطلاب
A2: سجل المستندات والوثائق الخاصة بشؤون الطلاب
A4: 🔙 العودة | E4: عدد المستندات: | H4: =COUNTA(B7:B100)-1
B6: رقم المستند | C6: نوع المستند | D6: التاريخ | E6: الموضوع | F6: الحالة | G6: مستوى السرية | H6: الرابط الإلكتروني | I6: صادر/وارد | J6: ملاحظات

Sheet التحصيل المالي
A1: 💰 قسم التحصيل المالي
A2: سجل المستندات والوثائق الخاصة بالتحصيل المالي
A4: 🔙 العودة | E4: عدد المستندات: | H4: =COUNTA(B7:B100)-1
B6: رقم المستند | C6: نوع المستند | D6: التاريخ | E6: الموضوع | F6: الحالة | G6: مستوى السرية | H6: الرابط الإلكتروني | I6: صادر/وارد | J6: ملاحظات

Sheet الشؤون المالية
A1: 🏦 قسم الشؤون المالية
A2: سجل المستندات والوثائق الخاصة بالشؤون المالية
A4: 🔙 العودة | E4: عدد المستندات: | H4: =COUNTA(B7:B100)-1
B6: رقم المستند | C6: نوع المستند | D6: التاريخ | E6: الموضوع | F6: الحالة | G6: مستوى السرية | H6: الرابط الإلكتروني | I6: صادر/وارد | J6: ملاحظات

Sheet الإدارة الأكاديمية
A1: 🎓 قسم الإدارة الأكاديمية
A2: سجل المستندات والوثائق الخاصة بالإدارة الأكاديمية
A4: 🔙 العودة | E4: عدد المستندات: | H4: =COUNTA(B7:B100)-1
B6: رقم المستند | C6: نوع المستند | D6: التاريخ | E6: الموضوع | F6: الحالة | G6: مستوى السرية | H6: الرابط الإلكتروني | I6: صادر/وارد | J6: ملاحظات

Sheet إدارة الجودة
A1: ⭐ قسم إدارة الجودة
A2: سجل المستندات والوثائق الخاصة بإدارة الجودة
A4: 🔙 العودة | E4: عدد المستندات: | H4: =COUNTA(B7:B100)-1
B6: رقم المستند | C6: نوع المستند | D6: التاريخ | E6: الموضوع | F6: الحالة | G6: مستوى السرية | H6: الرابط الإلكتروني | I6: صادر/وارد | J6: ملاحظات

Sheet الإدارة العليا
A1: 👔 قسم الإدارة العليا
A2: سجل المستندات والوثائق الخاصة بالإدارة العليا
A4: 🔙 العودة | E4: عدد المستندات: | H4: =COUNTA(B7:B100)-1
B6: رقم المستند | C6: نوع المستند | D6: التاريخ | E6: الموضوع | F6: الحالة | G6: مستوى السرية | H6: الرابط الإلكتروني | I6: صادر/وارد | J6: ملاحظات

Sheet المرافق والصيانة
A1: 🔧 قسم المرافق والصيانة
A2: سجل المستندات والوثائق الخاصة بالمرافق والصيانة
A4: 🔙 العودة | E4: عدد المستندات: | H4: =COUNTA(B7:B100)-1
B6: رقم المستند | C6: نوع المستند | D6: التاريخ | E6: الموضوع | F6: الحالة | G6: مستوى السرية | H6: الرابط الإلكتروني | I6: صادر/وارد | J6: ملاحظات

Sheet المستندات السرية
A1: 🔒 المستندات السرية والمشفرة
A2: ⚠️ تحذير: هذه المنطقة محمية - يتطلب الوصول كود أمان خاص
B4: 🔐 نظام التحقق من الهوية والصلاحيات
B5: 🔐 للوصول الآمن، يرجى استخدام نظام التحقق من الهوية
B6: كود الوصول المطلوب: | E6: [يتم الإدخال عبر النظام]
B7: المستخدم الحالي: | E7: مدير النظام
B8: مستوى الصلاحية: | E8: كامل الصلاحيات
B9: آخر محاولة دخول: | E9: 2026-01-02 14:35:22
B11: 📌 ملاحظة هامة: الوصول لهذه المستندات يُسجل تلقائياً في سجل النشاطات الأمنية
A13: 🔙 العودة للصفحة الرئيسية | E13: عدد المستندات السرية: | H13: 3
B15: رقم المستند | C15: القسم | D15: التاريخ | E15: الموضوع | F15: درجة السرية | G15: الرابط المشفر | H15: المخول بالاطلاع | I15: ملاحظات | J15: 🔑 الرقم السري
B16: SD-2026-001 | C16: الإدارة العليا | D16: 2026-01-15 | E16: محضر اجتماع سري لمجلس الإدارة | F16: سري للغاية | G16: enc://vault/SD-2026-001 | H16: مدير النظام | I16: يحظر النسخ أو المشاركة | J16: A9X7-4K2P
B17: SD-2026-002 | C17: نظام الوصول الآمن | D17: 2026-02-02 | E17: خطة الاستجابة للحوادث الأمنية | F17: سري | G17: enc://vault/SD-2026-002 | H17: مسؤول أمن المعلومات | I17: مراجعة ربع سنوية | J17: Q3M1-8ZT0
B18: SD-2026-003 | C18: الشؤون المالية | D18: 2026-02-18 | E18: بيانات تدقيق داخلي حساسة | F18: سري | G18: enc://vault/SD-2026-003 | H18: المدير المالي | I18: ممنوع الطباعة | J18: L5V2-1R8C
B31: ⚠️ تنبيه أمني: جميع محاولات الوصول مسجلة | لطلب صلاحيات جديدة، تواصل مع قسم أمن المعلومات
B33: 📋 أنواع الصلاحيات: [كامل الصلاحيات] | [قراءة فقط] | [قسم محدد] | [تحرير محدود]

Sheet التقارير
A1: 📊 التقارير والإحصائيات الشاملة
A2: تحليل شامل لبيانات المستندات والوثائق في جميع الأقسام
B4: 🔙 العودة للصفحة الرئيسية
B6: 📈 إحصائيات المستندات حسب الأقسام
B8: القسم | C8: إجمالي المستندات | D8: مستندات سرية | E8: مستندات عادية | F8: نسبة السرية % | G8: الحالة
B9: شؤون الطلاب | F9: =D9/C9
B10: التحصيل المالي | F10: =D10/C10
B11: الشؤون المالية | F11: =D11/C11
B12: الإدارة الأكاديمية | F12: =D12/C12
B13: إدارة الجودة | F13: =D13/C13
B14: الإدارة العليا | F14: =D14/C14
B15: المرافق والصيانة | F15: =D15/C15
B16: الإجمالي | C16: =SUM(C9:C15) | D16: =SUM(D9:D15) | E16: =SUM(E9:E15) | F16: =D16/C16 | G16: 7 أقسام نشطة
B19: 📑 تحليل أنواع المستندات
B21: نوع المستند | C21: العدد | D21: النسبة %
B22: عقد | D22: =C22/306
B23: تعميم | D23: =C23/306
B24: محضر اجتماع | D24: =C24/306
B25: خطاب وارد | D25: =C25/306
B26: خطاب صادر | D26: =C26/306
B27: المجموع | C27: =SUM(C22:C26) | D27: =SUM(D22:D26)
B30: 🔐 توزيع مستويات السرية
B32: مستوى السرية | C32: العدد | D32: النسبة % | E32: التصنيف
B33: عادي | D33: =C33/306 | E33: منخفض المخاطر
B34: مهم | D34: =C34/306 | E34: متوسط المخاطر
B35: سري | D35: =C35/306 | E35: عالي المخاطر
B36: سري للغاية | D36: =C36/306 | E36: حرج جداً
B37: المجموع | C37: =SUM(C33:C36) | D37: =SUM(D33:D36)
B41: 📅 تاريخ إنشاء التقرير: 2026-01-02 | يتم تحديث الإحصائيات تلقائياً

Sheet دليل الاستخدام
A1: 📖 دليل الاستخدام الشامل
A2: إرشادات تفصيلية لاستخدام نظام إدارة الوثائق والسجلات المؤسسية
B4: 🔙 العودة للصفحة الرئيسية
B6: 📋 نظرة عامة على النظام
B8: نظام إدارة الوثائق والسجلات المؤسسية هو منصة شاملة لإدارة جميع المستندات والوثائق في المعهد التعليمي. يتيح النظام:
B9: ✓ تسجيل وأرشفة المستندات بشكل منظم ومهني
B10: ✓ الوصول السريع للمستندات عبر الروابط الإلكترونية المباشرة
B11: ✓ تأمين المستندات السرية بنظام حماية متقدم
B12: ✓ إنشاء تقارير وإحصائيات تحليلية شاملة
B13: ✓ إدارة الصلاحيات والوصول حسب الأدوار الوظيفية
B15: 🎯 كيفية استخدام النظام
B17: 1️⃣ للوصول إلى قسم معين:
B18: - من الصفحة الرئيسية، انقر على اسم القسم المطلوب من قائمة الروابط السريعة
B19: - ستنتقل مباشرة إلى صفحة القسم لعرض جميع مستنداته
... B37: 🔐 جدول الصلاحيات وإدارة الوصول
B39: الدور الوظيفي | C39: صلاحيات المشاهدة | D39: صلاحيات التحرير | E39: الوصول للمستندات السرية | F39: إنشاء التقارير | G39: إدارة الصلاحيات
B40: مدير النظام | C40: كامل | D40: كامل | E40: كامل الوصول | F40: نعم | G40: نعم
B41: الإدارة العليا | C41: كامل | D41: محدود | E41: مستندات القسم فقط | F41: نعم | G41: لا
B42: مدير القسم | C42: قسمه فقط | D42: قسمه فقط | E42: حسب التصنيف | F42: قسمه فقط | G42: لا
B43: موظف إداري | C43: قسمه فقط | D43: قراءة فقط | E43: لا يوجد | F43: لا | G43: لا
B44: مدقق خارجي | C44: محدد مسبقاً | D44: لا يوجد | E44: حسب الحاجة | F44: قراءة فقط | G44: لا
B45: ضيف/زائر | C45: عامة فقط | D45: لا يوجد | E45: لا يوجد | F45: لا | G45: لا
B47: 📌 ملاحظة: لطلب تعديل الصلاحيات، يرجى التواصل مع مدير النظام أو قسم تقنية المعلومات
B50: 📑 دليل أنواع المستندات
B52: نوع المستند | C52: الوصف | D52: الأمثلة
B53: عقد | C53: اتفاقيات ملزمة قانونياً | D53: عقود تعيين، عقود شراكة، عقود صيانة
B54: تعميم | C54: إعلانات وتوجيهات رسمية | D54: تعاميم إدارية، قرارات تنظيمية
B55: محضر اجتماع | C55: توثيق الاجتماعات والقرارات | D55: محاضر اللجان، محاضر المجالس
B56: خطاب وارد | C56: مراسلات واردة من جهات خارجية | D56: خطابات رسمية، استفسارات
B57: خطاب صادر | C57: مراسلات صادرة لجهات خارجية | D57: ردود رسمية، طلبات
B60: 🔒 دليل مستويات السرية
B62: مستوى السرية | C62: الوصف | D62: من يمكنه الاطلاع
B63: عادي | C63: مستندات عامة غير حساسة | D63: جميع الموظفين حسب أقسامهم
B64: مهم | C64: مستندات متوسطة الحساسية | D64: رؤساء الأقسام والمديرون
B65: سري | C65: مستندات حساسة ومهمة | D65: الإدارة العليا ومدراء مخولون
B66: سري للغاية | C66: مستندات في غاية السرية والحساسية | D66: مجلس الإدارة والإدارة العليا فقط
B69: 💡 للدعم الفني: تواصل مع قسم تقنية المعلومات | البريد الإلكتروني: support@institute.edu.sa | الهاتف: 0123456789
B71: تم آخر تحديث للدليل: 2026-01-02 | الإصدار 1.0
B1003: 🔐 نظام الحماية والأمان
B1005: نظام التحقق من الهوية: | C1005: للوصول إلى المستندات السرية، يجب استخدام نظام التحقق من الهوية
...

Sheet تحليل النظام
A1: تحليل نظام الأرشفة
A3: ملخص الأقسام
A4: القسم | B4: عدد السجلات | C4: آخر صف
A5: شؤون الطلاب
A6: التحصيل المالي
A7: الشؤون المالية
A8: الإدارة الأكاديمية
A9: إدارة الجودة
A10: الإدارة العليا
A11: المرافق والصيانة
A12: المستندات السرية
A15: تحليل الصيغ الحالية
A16: الملاحظات:
A17: 1. العمود B يستخدم صيغة IF لجلب رقم المستند من الأقسام المختلفة
A18: 2. العمود M يستخدم صيغة IF للتحقق من كلمة المرور (2100)
... A29: 5. تحسين البنية لدعم إضافة سجلات جديدة بدون تعديل الصيغ

Sheet نظام الوصول الآمن
B5: 🔐 نظام التحقق من الهوية
B7: يرجى إدخال الرقم السري للوصول إلى المستندات السرية
B9: الرقم السري المطلوب: | D9: 2100
B11: =IF(D9=2100,"✅ تم التحقق بنجاح - يمكنك الوصول الآن","❌ الرقم السري غير صحيح")
B13: رابط المستندات السرية
B15: ملاحظة: الرقم السري هو 2100
B17: حالة النظام: | D17: =IF(D9=2100,"🟢 النظام نشط وجاهز","🔴 في انتظار كلمة المرور")

Sheet سجل النشاطات الأمنية
B2: 📋 سجل النشاطات الأمنية
B4: التاريخ والوقت | C4: نوع النشاط | D4: الحالة | E4: الملاحظات
B5: =NOW() | C5: تفعيل النظام | D5: ✅ ناجح | E5: تم تفعيل نظام الحماية المتقدم بكلمة المرور 2100
C6: محاولة وصول | D6: ⏳ قيد الانتظار | E6: في انتظار إدخال كلمة المرور
C7: مراجعة أمنية | D7: 🔍 جاري | E7: مراقبة الوصول للمستندات السرية
